{
 "cells": [
  {
   "cell_type": "markdown",
   "metadata": {},
   "source": [
    "### 作業\n",
    "請嘗試使用 keras 來定義一個直接預測 15 個人臉關鍵點坐標的檢測網路，以及適合這個網路的 loss function\n",
    "\n",
    "\n",
    "Hint: 參考前面的電腦視覺深度學習基礎"
   ]
  },
  {
   "cell_type": "markdown",
   "metadata": {},
   "source": [
    "### 範例\n",
    "接下來的程式碼會示範如何定義一個簡單的 CNN model"
   ]
  },
  {
   "cell_type": "code",
   "execution_count": 1,
   "metadata": {},
   "outputs": [],
   "source": [
    "import numpy as np\n",
    "import pandas as pd\n",
    "import matplotlib.pyplot as plt\n",
    "%matplotlib inline"
   ]
  },
  {
   "cell_type": "code",
   "execution_count": 2,
   "metadata": {},
   "outputs": [],
   "source": [
    "# 使用 colab 環境的同學請執行以下程式碼\n",
    "# %tensorflow_version 1.x # 確保 colob 中使用的 tensorflow 是 1.x 版本而不是 tensorflow 2\n",
    "# import tensorflow as tf\n",
    "# print(tf.__version__)\n",
    "\n",
    "# import os\n",
    "# from google.colab import drive \n",
    "# drive.mount('/content/gdrive') # 將 google drive 掛載在 colob，\n",
    "# %cd 'gdrive/My Drive'\n",
    "# os.system(\"mkdir cupoy_cv_part4\") # 可以自己改路徑\n",
    "# %cd cupoy_cv_part4 # 可以自己改路徑"
   ]
  },
  {
   "cell_type": "code",
   "execution_count": 3,
   "metadata": {},
   "outputs": [],
   "source": [
    "# 讀取資料集以及做前處理的函數\n",
    "def load_data(dirname):\n",
    "    # 讀取 csv 文件\n",
    "    data = pd.read_csv(dirname)\n",
    "    # 過濾有缺失值的 row\n",
    "    data = data.dropna()\n",
    "\n",
    "    # 將圖片像素值讀取為 numpy array 的形態\n",
    "    data['Image'] = data['Image'].apply(lambda img: np.fromstring(img, sep=' ')).values \n",
    "\n",
    "    # 單獨把圖像 array 抽取出來\n",
    "    imgs = np.vstack(data['Image'].values)/255\n",
    "    # reshape 為 96 x 96\n",
    "    imgs = imgs.reshape(data.shape[0], 96, 96)\n",
    "    # 轉換為 float\n",
    "    imgs = imgs.astype(np.float32)\n",
    "    \n",
    "    # 提取坐標的部分\n",
    "    points = data[data.columns[:-1]].values\n",
    "\n",
    "    # 轉換為 float\n",
    "    points = points.astype(np.float32)\n",
    "\n",
    "    # normalize 坐標值到 [-0.5, 0.5]\n",
    "    points = points/96 - 0.5\n",
    "    \n",
    "    return imgs, points"
   ]
  },
  {
   "cell_type": "code",
   "execution_count": 4,
   "metadata": {},
   "outputs": [
    {
     "name": "stdout",
     "output_type": "stream",
     "text": [
      "圖像資料: (2140, 96, 96) \n",
      "關鍵點資料: (2140, 30)\n"
     ]
    }
   ],
   "source": [
    "# 讀取資料\n",
    "imgs_train, points_train = load_data(dirname = 'training.csv')\n",
    "print(\"圖像資料:\", imgs_train.shape, \"\\n關鍵點資料:\", points_train.shape)"
   ]
  },
  {
   "cell_type": "code",
   "execution_count": 5,
   "metadata": {
    "scrolled": false
   },
   "outputs": [
    {
     "name": "stderr",
     "output_type": "stream",
     "text": [
      "Using TensorFlow backend.\n",
      "ERROR:root:Internal Python error in the inspect module.\n",
      "Below is the traceback from this internal error.\n",
      "\n",
      "ERROR:root:Internal Python error in the inspect module.\n",
      "Below is the traceback from this internal error.\n",
      "\n"
     ]
    },
    {
     "name": "stdout",
     "output_type": "stream",
     "text": [
      "Traceback (most recent call last):\n",
      "  File \"C:\\Users\\fisheden\\Anaconda3\\lib\\site-packages\\tensorflow_core\\python\\training\\tracking\\data_structures.py\", line 27, in <module>\n",
      "    import wrapt\n",
      "ModuleNotFoundError: No module named 'wrapt'\n",
      "\n",
      "During handling of the above exception, another exception occurred:\n",
      "\n",
      "Traceback (most recent call last):\n",
      "  File \"C:\\Users\\fisheden\\Anaconda3\\lib\\site-packages\\IPython\\core\\interactiveshell.py\", line 3331, in run_code\n",
      "    exec(code_obj, self.user_global_ns, self.user_ns)\n",
      "  File \"<ipython-input-5-2ec46501bef8>\", line 1, in <module>\n",
      "    from keras.models import Sequential\n",
      "  File \"C:\\Users\\fisheden\\Anaconda3\\lib\\site-packages\\keras\\__init__.py\", line 3, in <module>\n",
      "    from . import utils\n",
      "  File \"C:\\Users\\fisheden\\Anaconda3\\lib\\site-packages\\keras\\utils\\__init__.py\", line 6, in <module>\n",
      "    from . import conv_utils\n",
      "  File \"C:\\Users\\fisheden\\Anaconda3\\lib\\site-packages\\keras\\utils\\conv_utils.py\", line 9, in <module>\n",
      "    from .. import backend as K\n",
      "  File \"C:\\Users\\fisheden\\Anaconda3\\lib\\site-packages\\keras\\backend\\__init__.py\", line 1, in <module>\n",
      "    from .load_backend import epsilon\n",
      "  File \"C:\\Users\\fisheden\\Anaconda3\\lib\\site-packages\\keras\\backend\\load_backend.py\", line 90, in <module>\n",
      "    from .tensorflow_backend import *\n",
      "  File \"C:\\Users\\fisheden\\Anaconda3\\lib\\site-packages\\keras\\backend\\tensorflow_backend.py\", line 5, in <module>\n",
      "    import tensorflow as tf\n",
      "  File \"C:\\Users\\fisheden\\Anaconda3\\lib\\site-packages\\tensorflow\\__init__.py\", line 99, in <module>\n",
      "    from tensorflow_core import *\n",
      "  File \"C:\\Users\\fisheden\\Anaconda3\\lib\\site-packages\\tensorflow_core\\__init__.py\", line 28, in <module>\n",
      "    from tensorflow.python import pywrap_tensorflow  # pylint: disable=unused-import\n",
      "  File \"<frozen importlib._bootstrap>\", line 1019, in _handle_fromlist\n",
      "  File \"C:\\Users\\fisheden\\Anaconda3\\lib\\site-packages\\tensorflow\\__init__.py\", line 50, in __getattr__\n",
      "    module = self._load()\n",
      "  File \"C:\\Users\\fisheden\\Anaconda3\\lib\\site-packages\\tensorflow\\__init__.py\", line 44, in _load\n",
      "    module = _importlib.import_module(self.__name__)\n",
      "  File \"C:\\Users\\fisheden\\Anaconda3\\lib\\importlib\\__init__.py\", line 127, in import_module\n",
      "    return _bootstrap._gcd_import(name[level:], package, level)\n",
      "  File \"C:\\Users\\fisheden\\Anaconda3\\lib\\site-packages\\tensorflow_core\\python\\__init__.py\", line 73, in <module>\n",
      "    from tensorflow.python.ops.standard_ops import *\n",
      "  File \"C:\\Users\\fisheden\\Anaconda3\\lib\\site-packages\\tensorflow_core\\python\\ops\\standard_ops.py\", line 25, in <module>\n",
      "    from tensorflow.python import autograph\n",
      "  File \"C:\\Users\\fisheden\\Anaconda3\\lib\\site-packages\\tensorflow_core\\python\\autograph\\__init__.py\", line 35, in <module>\n",
      "    from tensorflow.python.autograph import operators\n",
      "  File \"C:\\Users\\fisheden\\Anaconda3\\lib\\site-packages\\tensorflow_core\\python\\autograph\\__init__.py\", line 35, in <module>\n",
      "    from tensorflow.python.autograph import operators\n",
      "  File \"C:\\Users\\fisheden\\Anaconda3\\lib\\site-packages\\tensorflow_core\\python\\autograph\\operators\\__init__.py\", line 40, in <module>\n",
      "    from tensorflow.python.autograph.operators.control_flow import for_stmt\n",
      "  File \"C:\\Users\\fisheden\\Anaconda3\\lib\\site-packages\\tensorflow_core\\python\\autograph\\operators\\control_flow.py\", line 65, in <module>\n",
      "    from tensorflow.python.autograph.operators import py_builtins\n",
      "  File \"C:\\Users\\fisheden\\Anaconda3\\lib\\site-packages\\tensorflow_core\\python\\autograph\\operators\\py_builtins.py\", line 30, in <module>\n",
      "    from tensorflow.python.data.ops import dataset_ops\n",
      "  File \"C:\\Users\\fisheden\\Anaconda3\\lib\\site-packages\\tensorflow_core\\python\\data\\__init__.py\", line 25, in <module>\n",
      "    from tensorflow.python.data import experimental\n",
      "  File \"C:\\Users\\fisheden\\Anaconda3\\lib\\site-packages\\tensorflow_core\\python\\data\\experimental\\__init__.py\", line 89, in <module>\n",
      "    from tensorflow.python.data.experimental.ops.batching import dense_to_sparse_batch\n",
      "  File \"C:\\Users\\fisheden\\Anaconda3\\lib\\site-packages\\tensorflow_core\\python\\data\\experimental\\ops\\batching.py\", line 20, in <module>\n",
      "    from tensorflow.python.data.ops import dataset_ops\n",
      "  File \"C:\\Users\\fisheden\\Anaconda3\\lib\\site-packages\\tensorflow_core\\python\\data\\ops\\dataset_ops.py\", line 70, in <module>\n",
      "    from tensorflow.python.training.tracking import tracking\n",
      "  File \"C:\\Users\\fisheden\\Anaconda3\\lib\\site-packages\\tensorflow_core\\python\\training\\tracking\\tracking.py\", line 29, in <module>\n",
      "    from tensorflow.python.training.tracking import data_structures\n",
      "  File \"C:\\Users\\fisheden\\Anaconda3\\lib\\site-packages\\tensorflow_core\\python\\training\\tracking\\data_structures.py\", line 30, in <module>\n",
      "    from .....third_party import wrapt\n",
      "ValueError: attempted relative import beyond top-level package\n",
      "\n",
      "During handling of the above exception, another exception occurred:\n",
      "\n",
      "Traceback (most recent call last):\n",
      "  File \"C:\\Users\\fisheden\\Anaconda3\\lib\\site-packages\\IPython\\core\\interactiveshell.py\", line 2044, in showtraceback\n",
      "    stb = value._render_traceback_()\n",
      "AttributeError: 'ValueError' object has no attribute '_render_traceback_'\n",
      "\n",
      "During handling of the above exception, another exception occurred:\n",
      "\n",
      "Traceback (most recent call last):\n",
      "  File \"C:\\Users\\fisheden\\Anaconda3\\lib\\site-packages\\tensorflow_core\\python\\training\\tracking\\data_structures.py\", line 27, in <module>\n",
      "    import wrapt\n",
      "ModuleNotFoundError: No module named 'wrapt'\n",
      "\n",
      "During handling of the above exception, another exception occurred:\n",
      "\n",
      "Traceback (most recent call last):\n",
      "  File \"C:\\Users\\fisheden\\Anaconda3\\lib\\site-packages\\IPython\\core\\ultratb.py\", line 1151, in get_records\n",
      "    return _fixed_getinnerframes(etb, number_of_lines_of_context, tb_offset)\n",
      "  File \"C:\\Users\\fisheden\\Anaconda3\\lib\\site-packages\\IPython\\core\\ultratb.py\", line 319, in wrapped\n",
      "    return f(*args, **kwargs)\n",
      "  File \"C:\\Users\\fisheden\\Anaconda3\\lib\\site-packages\\IPython\\core\\ultratb.py\", line 353, in _fixed_getinnerframes\n",
      "    records = fix_frame_records_filenames(inspect.getinnerframes(etb, context))\n",
      "  File \"C:\\Users\\fisheden\\Anaconda3\\lib\\inspect.py\", line 1502, in getinnerframes\n",
      "    frameinfo = (tb.tb_frame,) + getframeinfo(tb, context)\n",
      "  File \"C:\\Users\\fisheden\\Anaconda3\\lib\\inspect.py\", line 1460, in getframeinfo\n",
      "    filename = getsourcefile(frame) or getfile(frame)\n",
      "  File \"C:\\Users\\fisheden\\Anaconda3\\lib\\inspect.py\", line 696, in getsourcefile\n",
      "    if getattr(getmodule(object, filename), '__loader__', None) is not None:\n",
      "  File \"C:\\Users\\fisheden\\Anaconda3\\lib\\inspect.py\", line 733, in getmodule\n",
      "    if ismodule(module) and hasattr(module, '__file__'):\n",
      "  File \"C:\\Users\\fisheden\\Anaconda3\\lib\\site-packages\\tensorflow\\__init__.py\", line 50, in __getattr__\n",
      "    module = self._load()\n",
      "  File \"C:\\Users\\fisheden\\Anaconda3\\lib\\site-packages\\tensorflow\\__init__.py\", line 44, in _load\n",
      "    module = _importlib.import_module(self.__name__)\n",
      "  File \"C:\\Users\\fisheden\\Anaconda3\\lib\\importlib\\__init__.py\", line 127, in import_module\n",
      "    return _bootstrap._gcd_import(name[level:], package, level)\n",
      "  File \"<frozen importlib._bootstrap>\", line 1006, in _gcd_import\n",
      "  File \"<frozen importlib._bootstrap>\", line 983, in _find_and_load\n",
      "  File \"<frozen importlib._bootstrap>\", line 953, in _find_and_load_unlocked\n",
      "  File \"<frozen importlib._bootstrap>\", line 219, in _call_with_frames_removed\n",
      "  File \"<frozen importlib._bootstrap>\", line 1006, in _gcd_import\n",
      "  File \"<frozen importlib._bootstrap>\", line 983, in _find_and_load\n",
      "  File \"<frozen importlib._bootstrap>\", line 967, in _find_and_load_unlocked\n",
      "  File \"<frozen importlib._bootstrap>\", line 677, in _load_unlocked\n",
      "  File \"<frozen importlib._bootstrap_external>\", line 728, in exec_module\n",
      "  File \"<frozen importlib._bootstrap>\", line 219, in _call_with_frames_removed\n",
      "  File \"C:\\Users\\fisheden\\Anaconda3\\lib\\site-packages\\tensorflow_core\\__init__.py\", line 34, in <module>\n",
      "    from tensorflow._api.v1 import autograph\n",
      "  File \"C:\\Users\\fisheden\\Anaconda3\\lib\\site-packages\\tensorflow_core\\_api\\v1\\autograph\\__init__.py\", line 22, in <module>\n",
      "    from tensorflow._api.v1.autograph import experimental\n",
      "  File \"C:\\Users\\fisheden\\Anaconda3\\lib\\site-packages\\tensorflow_core\\_api\\v1\\autograph\\experimental\\__init__.py\", line 10, in <module>\n",
      "    from tensorflow.python.autograph.core.converter import Feature\n",
      "  File \"C:\\Users\\fisheden\\Anaconda3\\lib\\site-packages\\tensorflow_core\\python\\autograph\\__init__.py\", line 35, in <module>\n",
      "    from tensorflow.python.autograph import operators\n",
      "  File \"C:\\Users\\fisheden\\Anaconda3\\lib\\site-packages\\tensorflow_core\\python\\autograph\\operators\\__init__.py\", line 40, in <module>\n",
      "    from tensorflow.python.autograph.operators.control_flow import for_stmt\n",
      "  File \"C:\\Users\\fisheden\\Anaconda3\\lib\\site-packages\\tensorflow_core\\python\\autograph\\operators\\control_flow.py\", line 65, in <module>\n",
      "    from tensorflow.python.autograph.operators import py_builtins\n",
      "  File \"C:\\Users\\fisheden\\Anaconda3\\lib\\site-packages\\tensorflow_core\\python\\autograph\\operators\\py_builtins.py\", line 30, in <module>\n",
      "    from tensorflow.python.data.ops import dataset_ops\n",
      "  File \"C:\\Users\\fisheden\\Anaconda3\\lib\\site-packages\\tensorflow_core\\python\\data\\ops\\dataset_ops.py\", line 70, in <module>\n",
      "    from tensorflow.python.training.tracking import tracking\n",
      "  File \"C:\\Users\\fisheden\\Anaconda3\\lib\\site-packages\\tensorflow_core\\python\\training\\tracking\\tracking.py\", line 29, in <module>\n",
      "    from tensorflow.python.training.tracking import data_structures\n",
      "  File \"C:\\Users\\fisheden\\Anaconda3\\lib\\site-packages\\tensorflow_core\\python\\training\\tracking\\data_structures.py\", line 30, in <module>\n",
      "    from .....third_party import wrapt\n",
      "ValueError: attempted relative import beyond top-level package\n",
      "Traceback (most recent call last):\n",
      "  File \"C:\\Users\\fisheden\\Anaconda3\\lib\\site-packages\\tensorflow_core\\python\\training\\tracking\\data_structures.py\", line 27, in <module>\n",
      "    import wrapt\n",
      "ModuleNotFoundError: No module named 'wrapt'\n",
      "\n",
      "During handling of the above exception, another exception occurred:\n",
      "\n",
      "Traceback (most recent call last):\n",
      "  File \"C:\\Users\\fisheden\\Anaconda3\\lib\\site-packages\\IPython\\core\\interactiveshell.py\", line 3331, in run_code\n",
      "    exec(code_obj, self.user_global_ns, self.user_ns)\n",
      "  File \"<ipython-input-5-2ec46501bef8>\", line 1, in <module>\n",
      "    from keras.models import Sequential\n",
      "  File \"C:\\Users\\fisheden\\Anaconda3\\lib\\site-packages\\keras\\__init__.py\", line 3, in <module>\n",
      "    from . import utils\n",
      "  File \"C:\\Users\\fisheden\\Anaconda3\\lib\\site-packages\\keras\\utils\\__init__.py\", line 6, in <module>\n",
      "    from . import conv_utils\n",
      "  File \"C:\\Users\\fisheden\\Anaconda3\\lib\\site-packages\\keras\\utils\\conv_utils.py\", line 9, in <module>\n",
      "    from .. import backend as K\n",
      "  File \"C:\\Users\\fisheden\\Anaconda3\\lib\\site-packages\\keras\\backend\\__init__.py\", line 1, in <module>\n",
      "    from .load_backend import epsilon\n",
      "  File \"C:\\Users\\fisheden\\Anaconda3\\lib\\site-packages\\keras\\backend\\load_backend.py\", line 90, in <module>\n",
      "    from .tensorflow_backend import *\n",
      "  File \"C:\\Users\\fisheden\\Anaconda3\\lib\\site-packages\\keras\\backend\\tensorflow_backend.py\", line 5, in <module>\n",
      "    import tensorflow as tf\n",
      "  File \"C:\\Users\\fisheden\\Anaconda3\\lib\\site-packages\\tensorflow\\__init__.py\", line 99, in <module>\n",
      "    from tensorflow_core import *\n",
      "  File \"C:\\Users\\fisheden\\Anaconda3\\lib\\site-packages\\tensorflow_core\\__init__.py\", line 28, in <module>\n",
      "    from tensorflow.python import pywrap_tensorflow  # pylint: disable=unused-import\n",
      "  File \"<frozen importlib._bootstrap>\", line 1019, in _handle_fromlist\n",
      "  File \"C:\\Users\\fisheden\\Anaconda3\\lib\\site-packages\\tensorflow\\__init__.py\", line 50, in __getattr__\n",
      "    module = self._load()\n",
      "  File \"C:\\Users\\fisheden\\Anaconda3\\lib\\site-packages\\tensorflow\\__init__.py\", line 44, in _load\n",
      "    module = _importlib.import_module(self.__name__)\n",
      "  File \"C:\\Users\\fisheden\\Anaconda3\\lib\\importlib\\__init__.py\", line 127, in import_module\n",
      "    return _bootstrap._gcd_import(name[level:], package, level)\n",
      "  File \"C:\\Users\\fisheden\\Anaconda3\\lib\\site-packages\\tensorflow_core\\python\\__init__.py\", line 73, in <module>\n",
      "    from tensorflow.python.ops.standard_ops import *\n",
      "  File \"C:\\Users\\fisheden\\Anaconda3\\lib\\site-packages\\tensorflow_core\\python\\ops\\standard_ops.py\", line 25, in <module>\n",
      "    from tensorflow.python import autograph\n",
      "  File \"C:\\Users\\fisheden\\Anaconda3\\lib\\site-packages\\tensorflow_core\\python\\autograph\\__init__.py\", line 35, in <module>\n",
      "    from tensorflow.python.autograph import operators\n",
      "  File \"C:\\Users\\fisheden\\Anaconda3\\lib\\site-packages\\tensorflow_core\\python\\autograph\\__init__.py\", line 35, in <module>\n",
      "    from tensorflow.python.autograph import operators\n",
      "  File \"C:\\Users\\fisheden\\Anaconda3\\lib\\site-packages\\tensorflow_core\\python\\autograph\\operators\\__init__.py\", line 40, in <module>\n",
      "    from tensorflow.python.autograph.operators.control_flow import for_stmt\n",
      "  File \"C:\\Users\\fisheden\\Anaconda3\\lib\\site-packages\\tensorflow_core\\python\\autograph\\operators\\control_flow.py\", line 65, in <module>\n",
      "    from tensorflow.python.autograph.operators import py_builtins\n",
      "  File \"C:\\Users\\fisheden\\Anaconda3\\lib\\site-packages\\tensorflow_core\\python\\autograph\\operators\\py_builtins.py\", line 30, in <module>\n",
      "    from tensorflow.python.data.ops import dataset_ops\n",
      "  File \"C:\\Users\\fisheden\\Anaconda3\\lib\\site-packages\\tensorflow_core\\python\\data\\__init__.py\", line 25, in <module>\n",
      "    from tensorflow.python.data import experimental\n",
      "  File \"C:\\Users\\fisheden\\Anaconda3\\lib\\site-packages\\tensorflow_core\\python\\data\\experimental\\__init__.py\", line 89, in <module>\n",
      "    from tensorflow.python.data.experimental.ops.batching import dense_to_sparse_batch\n",
      "  File \"C:\\Users\\fisheden\\Anaconda3\\lib\\site-packages\\tensorflow_core\\python\\data\\experimental\\ops\\batching.py\", line 20, in <module>\n",
      "    from tensorflow.python.data.ops import dataset_ops\n",
      "  File \"C:\\Users\\fisheden\\Anaconda3\\lib\\site-packages\\tensorflow_core\\python\\data\\ops\\dataset_ops.py\", line 70, in <module>\n",
      "    from tensorflow.python.training.tracking import tracking\n",
      "  File \"C:\\Users\\fisheden\\Anaconda3\\lib\\site-packages\\tensorflow_core\\python\\training\\tracking\\tracking.py\", line 29, in <module>\n",
      "    from tensorflow.python.training.tracking import data_structures\n",
      "  File \"C:\\Users\\fisheden\\Anaconda3\\lib\\site-packages\\tensorflow_core\\python\\training\\tracking\\data_structures.py\", line 30, in <module>\n",
      "    from .....third_party import wrapt\n",
      "ValueError: attempted relative import beyond top-level package\n",
      "\n",
      "During handling of the above exception, another exception occurred:\n",
      "\n",
      "Traceback (most recent call last):\n",
      "  File \"C:\\Users\\fisheden\\Anaconda3\\lib\\site-packages\\IPython\\core\\interactiveshell.py\", line 2044, in showtraceback\n",
      "    stb = value._render_traceback_()\n",
      "AttributeError: 'ValueError' object has no attribute '_render_traceback_'\n",
      "\n",
      "During handling of the above exception, another exception occurred:\n",
      "\n",
      "Traceback (most recent call last):\n",
      "  File \"C:\\Users\\fisheden\\Anaconda3\\lib\\site-packages\\IPython\\core\\interactiveshell.py\", line 3254, in run_ast_nodes\n",
      "    if (await self.run_code(code, result,  async_=asy)):\n",
      "  File \"C:\\Users\\fisheden\\Anaconda3\\lib\\site-packages\\IPython\\core\\interactiveshell.py\", line 3348, in run_code\n",
      "    self.showtraceback(running_compiled_code=True)\n",
      "  File \"C:\\Users\\fisheden\\Anaconda3\\lib\\site-packages\\IPython\\core\\interactiveshell.py\", line 2047, in showtraceback\n",
      "    value, tb, tb_offset=tb_offset)\n",
      "  File \"C:\\Users\\fisheden\\Anaconda3\\lib\\site-packages\\IPython\\core\\ultratb.py\", line 1418, in structured_traceback\n",
      "    self, etype, value, tb, tb_offset, number_of_lines_of_context)\n",
      "  File \"C:\\Users\\fisheden\\Anaconda3\\lib\\site-packages\\IPython\\core\\ultratb.py\", line 1318, in structured_traceback\n",
      "    self, etype, value, tb, tb_offset, number_of_lines_of_context\n",
      "  File \"C:\\Users\\fisheden\\Anaconda3\\lib\\site-packages\\IPython\\core\\ultratb.py\", line 1186, in structured_traceback\n",
      "    formatted_exceptions += self.prepare_chained_exception_message(evalue.__cause__)\n",
      "TypeError: can only concatenate str (not \"list\") to str\n",
      "\n",
      "During handling of the above exception, another exception occurred:\n",
      "\n",
      "Traceback (most recent call last):\n",
      "  File \"C:\\Users\\fisheden\\Anaconda3\\lib\\site-packages\\IPython\\core\\interactiveshell.py\", line 2044, in showtraceback\n",
      "    stb = value._render_traceback_()\n",
      "AttributeError: 'TypeError' object has no attribute '_render_traceback_'\n",
      "\n",
      "During handling of the above exception, another exception occurred:\n",
      "\n",
      "Traceback (most recent call last):\n",
      "  File \"C:\\Users\\fisheden\\Anaconda3\\lib\\site-packages\\tensorflow_core\\python\\training\\tracking\\data_structures.py\", line 27, in <module>\n",
      "    import wrapt\n",
      "ModuleNotFoundError: No module named 'wrapt'\n",
      "\n",
      "During handling of the above exception, another exception occurred:\n",
      "\n",
      "Traceback (most recent call last):\n",
      "  File \"C:\\Users\\fisheden\\Anaconda3\\lib\\site-packages\\IPython\\core\\ultratb.py\", line 1151, in get_records\n",
      "    return _fixed_getinnerframes(etb, number_of_lines_of_context, tb_offset)\n",
      "  File \"C:\\Users\\fisheden\\Anaconda3\\lib\\site-packages\\IPython\\core\\ultratb.py\", line 319, in wrapped\n",
      "    return f(*args, **kwargs)\n",
      "  File \"C:\\Users\\fisheden\\Anaconda3\\lib\\site-packages\\IPython\\core\\ultratb.py\", line 353, in _fixed_getinnerframes\n",
      "    records = fix_frame_records_filenames(inspect.getinnerframes(etb, context))\n",
      "  File \"C:\\Users\\fisheden\\Anaconda3\\lib\\inspect.py\", line 1502, in getinnerframes\n",
      "    frameinfo = (tb.tb_frame,) + getframeinfo(tb, context)\n",
      "  File \"C:\\Users\\fisheden\\Anaconda3\\lib\\inspect.py\", line 1460, in getframeinfo\n",
      "    filename = getsourcefile(frame) or getfile(frame)\n",
      "  File \"C:\\Users\\fisheden\\Anaconda3\\lib\\inspect.py\", line 696, in getsourcefile\n",
      "    if getattr(getmodule(object, filename), '__loader__', None) is not None:\n",
      "  File \"C:\\Users\\fisheden\\Anaconda3\\lib\\inspect.py\", line 733, in getmodule\n",
      "    if ismodule(module) and hasattr(module, '__file__'):\n",
      "  File \"C:\\Users\\fisheden\\Anaconda3\\lib\\site-packages\\tensorflow\\__init__.py\", line 50, in __getattr__\n",
      "    module = self._load()\n",
      "  File \"C:\\Users\\fisheden\\Anaconda3\\lib\\site-packages\\tensorflow\\__init__.py\", line 44, in _load\n",
      "    module = _importlib.import_module(self.__name__)\n",
      "  File \"C:\\Users\\fisheden\\Anaconda3\\lib\\importlib\\__init__.py\", line 127, in import_module\n",
      "    return _bootstrap._gcd_import(name[level:], package, level)\n",
      "  File \"<frozen importlib._bootstrap>\", line 1006, in _gcd_import\n",
      "  File \"<frozen importlib._bootstrap>\", line 983, in _find_and_load\n",
      "  File \"<frozen importlib._bootstrap>\", line 953, in _find_and_load_unlocked\n",
      "  File \"<frozen importlib._bootstrap>\", line 219, in _call_with_frames_removed\n",
      "  File \"<frozen importlib._bootstrap>\", line 1006, in _gcd_import\n",
      "  File \"<frozen importlib._bootstrap>\", line 983, in _find_and_load\n",
      "  File \"<frozen importlib._bootstrap>\", line 967, in _find_and_load_unlocked\n",
      "  File \"<frozen importlib._bootstrap>\", line 677, in _load_unlocked\n",
      "  File \"<frozen importlib._bootstrap_external>\", line 728, in exec_module\n",
      "  File \"<frozen importlib._bootstrap>\", line 219, in _call_with_frames_removed\n",
      "  File \"C:\\Users\\fisheden\\Anaconda3\\lib\\site-packages\\tensorflow_core\\__init__.py\", line 34, in <module>\n",
      "    from tensorflow._api.v1 import autograph\n",
      "  File \"C:\\Users\\fisheden\\Anaconda3\\lib\\site-packages\\tensorflow_core\\_api\\v1\\autograph\\__init__.py\", line 22, in <module>\n",
      "    from tensorflow._api.v1.autograph import experimental\n",
      "  File \"C:\\Users\\fisheden\\Anaconda3\\lib\\site-packages\\tensorflow_core\\_api\\v1\\autograph\\experimental\\__init__.py\", line 10, in <module>\n",
      "    from tensorflow.python.autograph.core.converter import Feature\n",
      "  File \"C:\\Users\\fisheden\\Anaconda3\\lib\\site-packages\\tensorflow_core\\python\\autograph\\__init__.py\", line 35, in <module>\n",
      "    from tensorflow.python.autograph import operators\n",
      "  File \"C:\\Users\\fisheden\\Anaconda3\\lib\\site-packages\\tensorflow_core\\python\\autograph\\operators\\__init__.py\", line 40, in <module>\n",
      "    from tensorflow.python.autograph.operators.control_flow import for_stmt\n",
      "  File \"C:\\Users\\fisheden\\Anaconda3\\lib\\site-packages\\tensorflow_core\\python\\autograph\\operators\\control_flow.py\", line 65, in <module>\n",
      "    from tensorflow.python.autograph.operators import py_builtins\n",
      "  File \"C:\\Users\\fisheden\\Anaconda3\\lib\\site-packages\\tensorflow_core\\python\\autograph\\operators\\py_builtins.py\", line 30, in <module>\n",
      "    from tensorflow.python.data.ops import dataset_ops\n",
      "  File \"C:\\Users\\fisheden\\Anaconda3\\lib\\site-packages\\tensorflow_core\\python\\data\\ops\\dataset_ops.py\", line 70, in <module>\n",
      "    from tensorflow.python.training.tracking import tracking\n",
      "  File \"C:\\Users\\fisheden\\Anaconda3\\lib\\site-packages\\tensorflow_core\\python\\training\\tracking\\tracking.py\", line 29, in <module>\n",
      "    from tensorflow.python.training.tracking import data_structures\n",
      "  File \"C:\\Users\\fisheden\\Anaconda3\\lib\\site-packages\\tensorflow_core\\python\\training\\tracking\\data_structures.py\", line 30, in <module>\n",
      "    from .....third_party import wrapt\n",
      "ValueError: attempted relative import beyond top-level package\n"
     ]
    },
    {
     "ename": "TypeError",
     "evalue": "can only concatenate str (not \"list\") to str",
     "output_type": "error",
     "traceback": [
      "\u001b[1;31m---------------------------------------------------------------------------\u001b[0m",
      "\u001b[1;31mModuleNotFoundError\u001b[0m                       Traceback (most recent call last)",
      "\u001b[1;32m~\\Anaconda3\\lib\\site-packages\\tensorflow_core\\python\\training\\tracking\\data_structures.py\u001b[0m in \u001b[0;36m<module>\u001b[1;34m\u001b[0m\n\u001b[0;32m     26\u001b[0m \u001b[1;32mtry\u001b[0m\u001b[1;33m:\u001b[0m\u001b[1;33m\u001b[0m\u001b[1;33m\u001b[0m\u001b[0m\n\u001b[1;32m---> 27\u001b[1;33m   \u001b[1;32mimport\u001b[0m \u001b[0mwrapt\u001b[0m\u001b[1;33m\u001b[0m\u001b[1;33m\u001b[0m\u001b[0m\n\u001b[0m\u001b[0;32m     28\u001b[0m \u001b[1;32mexcept\u001b[0m \u001b[0mImportError\u001b[0m\u001b[1;33m:\u001b[0m\u001b[1;33m\u001b[0m\u001b[1;33m\u001b[0m\u001b[0m\n",
      "\u001b[1;31mModuleNotFoundError\u001b[0m: No module named 'wrapt'",
      "\nDuring handling of the above exception, another exception occurred:\n",
      "\nDuring handling of the above exception, another exception occurred:\n",
      "\u001b[1;31mAttributeError\u001b[0m                            Traceback (most recent call last)",
      "\u001b[1;32m~\\Anaconda3\\lib\\site-packages\\IPython\\core\\interactiveshell.py\u001b[0m in \u001b[0;36mshowtraceback\u001b[1;34m(self, exc_tuple, filename, tb_offset, exception_only, running_compiled_code)\u001b[0m\n\u001b[0;32m   2043\u001b[0m                         \u001b[1;31m# in the engines. This should return a list of strings.\u001b[0m\u001b[1;33m\u001b[0m\u001b[1;33m\u001b[0m\u001b[1;33m\u001b[0m\u001b[0m\n\u001b[1;32m-> 2044\u001b[1;33m                         \u001b[0mstb\u001b[0m \u001b[1;33m=\u001b[0m \u001b[0mvalue\u001b[0m\u001b[1;33m.\u001b[0m\u001b[0m_render_traceback_\u001b[0m\u001b[1;33m(\u001b[0m\u001b[1;33m)\u001b[0m\u001b[1;33m\u001b[0m\u001b[1;33m\u001b[0m\u001b[0m\n\u001b[0m\u001b[0;32m   2045\u001b[0m                     \u001b[1;32mexcept\u001b[0m \u001b[0mException\u001b[0m\u001b[1;33m:\u001b[0m\u001b[1;33m\u001b[0m\u001b[1;33m\u001b[0m\u001b[0m\n",
      "\u001b[1;31mAttributeError\u001b[0m: 'ValueError' object has no attribute '_render_traceback_'",
      "\nDuring handling of the above exception, another exception occurred:\n",
      "\u001b[1;31mTypeError\u001b[0m                                 Traceback (most recent call last)",
      "\u001b[1;32m~\\Anaconda3\\lib\\site-packages\\IPython\\core\\interactiveshell.py\u001b[0m in \u001b[0;36mrun_code\u001b[1;34m(self, code_obj, result, async_)\u001b[0m\n\u001b[0;32m   3346\u001b[0m             \u001b[1;32mif\u001b[0m \u001b[0mresult\u001b[0m \u001b[1;32mis\u001b[0m \u001b[1;32mnot\u001b[0m \u001b[1;32mNone\u001b[0m\u001b[1;33m:\u001b[0m\u001b[1;33m\u001b[0m\u001b[1;33m\u001b[0m\u001b[0m\n\u001b[0;32m   3347\u001b[0m                 \u001b[0mresult\u001b[0m\u001b[1;33m.\u001b[0m\u001b[0merror_in_exec\u001b[0m \u001b[1;33m=\u001b[0m \u001b[0msys\u001b[0m\u001b[1;33m.\u001b[0m\u001b[0mexc_info\u001b[0m\u001b[1;33m(\u001b[0m\u001b[1;33m)\u001b[0m\u001b[1;33m[\u001b[0m\u001b[1;36m1\u001b[0m\u001b[1;33m]\u001b[0m\u001b[1;33m\u001b[0m\u001b[1;33m\u001b[0m\u001b[0m\n\u001b[1;32m-> 3348\u001b[1;33m             \u001b[0mself\u001b[0m\u001b[1;33m.\u001b[0m\u001b[0mshowtraceback\u001b[0m\u001b[1;33m(\u001b[0m\u001b[0mrunning_compiled_code\u001b[0m\u001b[1;33m=\u001b[0m\u001b[1;32mTrue\u001b[0m\u001b[1;33m)\u001b[0m\u001b[1;33m\u001b[0m\u001b[1;33m\u001b[0m\u001b[0m\n\u001b[0m\u001b[0;32m   3349\u001b[0m         \u001b[1;32melse\u001b[0m\u001b[1;33m:\u001b[0m\u001b[1;33m\u001b[0m\u001b[1;33m\u001b[0m\u001b[0m\n\u001b[0;32m   3350\u001b[0m             \u001b[0moutflag\u001b[0m \u001b[1;33m=\u001b[0m \u001b[1;32mFalse\u001b[0m\u001b[1;33m\u001b[0m\u001b[1;33m\u001b[0m\u001b[0m\n",
      "\u001b[1;32m~\\Anaconda3\\lib\\site-packages\\IPython\\core\\interactiveshell.py\u001b[0m in \u001b[0;36mshowtraceback\u001b[1;34m(self, exc_tuple, filename, tb_offset, exception_only, running_compiled_code)\u001b[0m\n\u001b[0;32m   2045\u001b[0m                     \u001b[1;32mexcept\u001b[0m \u001b[0mException\u001b[0m\u001b[1;33m:\u001b[0m\u001b[1;33m\u001b[0m\u001b[1;33m\u001b[0m\u001b[0m\n\u001b[0;32m   2046\u001b[0m                         stb = self.InteractiveTB.structured_traceback(etype,\n\u001b[1;32m-> 2047\u001b[1;33m                                             value, tb, tb_offset=tb_offset)\n\u001b[0m\u001b[0;32m   2048\u001b[0m \u001b[1;33m\u001b[0m\u001b[0m\n\u001b[0;32m   2049\u001b[0m                     \u001b[0mself\u001b[0m\u001b[1;33m.\u001b[0m\u001b[0m_showtraceback\u001b[0m\u001b[1;33m(\u001b[0m\u001b[0metype\u001b[0m\u001b[1;33m,\u001b[0m \u001b[0mvalue\u001b[0m\u001b[1;33m,\u001b[0m \u001b[0mstb\u001b[0m\u001b[1;33m)\u001b[0m\u001b[1;33m\u001b[0m\u001b[1;33m\u001b[0m\u001b[0m\n",
      "\u001b[1;32m~\\Anaconda3\\lib\\site-packages\\IPython\\core\\ultratb.py\u001b[0m in \u001b[0;36mstructured_traceback\u001b[1;34m(self, etype, value, tb, tb_offset, number_of_lines_of_context)\u001b[0m\n\u001b[0;32m   1416\u001b[0m             \u001b[0mself\u001b[0m\u001b[1;33m.\u001b[0m\u001b[0mtb\u001b[0m \u001b[1;33m=\u001b[0m \u001b[0mtb\u001b[0m\u001b[1;33m\u001b[0m\u001b[1;33m\u001b[0m\u001b[0m\n\u001b[0;32m   1417\u001b[0m         return FormattedTB.structured_traceback(\n\u001b[1;32m-> 1418\u001b[1;33m             self, etype, value, tb, tb_offset, number_of_lines_of_context)\n\u001b[0m\u001b[0;32m   1419\u001b[0m \u001b[1;33m\u001b[0m\u001b[0m\n\u001b[0;32m   1420\u001b[0m \u001b[1;33m\u001b[0m\u001b[0m\n",
      "\u001b[1;32m~\\Anaconda3\\lib\\site-packages\\IPython\\core\\ultratb.py\u001b[0m in \u001b[0;36mstructured_traceback\u001b[1;34m(self, etype, value, tb, tb_offset, number_of_lines_of_context)\u001b[0m\n\u001b[0;32m   1316\u001b[0m             \u001b[1;31m# Verbose modes need a full traceback\u001b[0m\u001b[1;33m\u001b[0m\u001b[1;33m\u001b[0m\u001b[1;33m\u001b[0m\u001b[0m\n\u001b[0;32m   1317\u001b[0m             return VerboseTB.structured_traceback(\n\u001b[1;32m-> 1318\u001b[1;33m                 \u001b[0mself\u001b[0m\u001b[1;33m,\u001b[0m \u001b[0metype\u001b[0m\u001b[1;33m,\u001b[0m \u001b[0mvalue\u001b[0m\u001b[1;33m,\u001b[0m \u001b[0mtb\u001b[0m\u001b[1;33m,\u001b[0m \u001b[0mtb_offset\u001b[0m\u001b[1;33m,\u001b[0m \u001b[0mnumber_of_lines_of_context\u001b[0m\u001b[1;33m\u001b[0m\u001b[1;33m\u001b[0m\u001b[0m\n\u001b[0m\u001b[0;32m   1319\u001b[0m             )\n\u001b[0;32m   1320\u001b[0m         \u001b[1;32melif\u001b[0m \u001b[0mmode\u001b[0m \u001b[1;33m==\u001b[0m \u001b[1;34m'Minimal'\u001b[0m\u001b[1;33m:\u001b[0m\u001b[1;33m\u001b[0m\u001b[1;33m\u001b[0m\u001b[0m\n",
      "\u001b[1;32m~\\Anaconda3\\lib\\site-packages\\IPython\\core\\ultratb.py\u001b[0m in \u001b[0;36mstructured_traceback\u001b[1;34m(self, etype, evalue, etb, tb_offset, number_of_lines_of_context)\u001b[0m\n\u001b[0;32m   1184\u001b[0m         \u001b[0mexception\u001b[0m \u001b[1;33m=\u001b[0m \u001b[0mself\u001b[0m\u001b[1;33m.\u001b[0m\u001b[0mget_parts_of_chained_exception\u001b[0m\u001b[1;33m(\u001b[0m\u001b[0mevalue\u001b[0m\u001b[1;33m)\u001b[0m\u001b[1;33m\u001b[0m\u001b[1;33m\u001b[0m\u001b[0m\n\u001b[0;32m   1185\u001b[0m         \u001b[1;32mif\u001b[0m \u001b[0mexception\u001b[0m\u001b[1;33m:\u001b[0m\u001b[1;33m\u001b[0m\u001b[1;33m\u001b[0m\u001b[0m\n\u001b[1;32m-> 1186\u001b[1;33m             \u001b[0mformatted_exceptions\u001b[0m \u001b[1;33m+=\u001b[0m \u001b[0mself\u001b[0m\u001b[1;33m.\u001b[0m\u001b[0mprepare_chained_exception_message\u001b[0m\u001b[1;33m(\u001b[0m\u001b[0mevalue\u001b[0m\u001b[1;33m.\u001b[0m\u001b[0m__cause__\u001b[0m\u001b[1;33m)\u001b[0m\u001b[1;33m\u001b[0m\u001b[1;33m\u001b[0m\u001b[0m\n\u001b[0m\u001b[0;32m   1187\u001b[0m             \u001b[0metype\u001b[0m\u001b[1;33m,\u001b[0m \u001b[0mevalue\u001b[0m\u001b[1;33m,\u001b[0m \u001b[0metb\u001b[0m \u001b[1;33m=\u001b[0m \u001b[0mexception\u001b[0m\u001b[1;33m\u001b[0m\u001b[1;33m\u001b[0m\u001b[0m\n\u001b[0;32m   1188\u001b[0m         \u001b[1;32melse\u001b[0m\u001b[1;33m:\u001b[0m\u001b[1;33m\u001b[0m\u001b[1;33m\u001b[0m\u001b[0m\n",
      "\u001b[1;31mTypeError\u001b[0m: can only concatenate str (not \"list\") to str"
     ]
    }
   ],
   "source": [
    "from keras.models import Sequential\n",
    "from keras.layers import Conv2D, MaxPooling2D, Flatten, Dense, Dropout\n",
    "from keras.optimizers import Adam"
   ]
  },
  {
   "cell_type": "code",
   "execution_count": null,
   "metadata": {},
   "outputs": [],
   "source": [
    "# 定義人臉關鍵點檢測網路\n",
    "model = Sequential()\n",
    "\n",
    "# 定義神經網路的輸入, hidden layer 以及輸出\n",
    "model.add(Conv2D(filters=16, kernel_size=3, activation='relu', input_shape=(96, 96, 1)))\n",
    "model.add(MaxPooling2D(pool_size=2))\n",
    "\n",
    "model.add(Conv2D(filters=32, kernel_size=3, activation='relu'))\n",
    "model.add(MaxPooling2D(pool_size=2))\n",
    "\n",
    "model.add(Conv2D(filters=64, kernel_size=3, activation='relu'))\n",
    "model.add(MaxPooling2D(pool_size=2))\n",
    "\n",
    "model.add(Conv2D(filters=128, kernel_size=3, activation='relu'))\n",
    "model.add(MaxPooling2D(pool_size=2))\n",
    "\n",
    "model.add(Flatten())\n",
    "model.add(Dense(512, activation='relu'))\n",
    "model.add(Dropout(0.2))\n",
    "model.add(Dense(512, activation='relu'))\n",
    "model.add(Dropout(0.2))\n",
    "\n",
    "model.add(Dense(30))\n",
    "\n",
    "\n",
    "\n",
    "# 配置 loss funtion 和 optimizer\n",
    "\n",
    "model.compile(loss='mean_squared_error', optimizer='adam', metrics=['accuracy'])"
   ]
  },
  {
   "cell_type": "code",
   "execution_count": null,
   "metadata": {},
   "outputs": [],
   "source": []
  },
  {
   "cell_type": "code",
   "execution_count": null,
   "metadata": {},
   "outputs": [],
   "source": []
  }
 ],
 "metadata": {
  "kernelspec": {
   "display_name": "Python 3",
   "language": "python",
   "name": "python3"
  },
  "language_info": {
   "codemirror_mode": {
    "name": "ipython",
    "version": 3
   },
   "file_extension": ".py",
   "mimetype": "text/x-python",
   "name": "python",
   "nbconvert_exporter": "python",
   "pygments_lexer": "ipython3",
   "version": "3.7.6"
  }
 },
 "nbformat": 4,
 "nbformat_minor": 2
}
